2019-10-08 22:05:02,908 INFO Connecting to TGC socket...
2019-10-08 22:05:03,935 INFO Connected.
2019-10-08 22:05:03,935 INFO Recording brain data...
2019-10-08 22:07:23,594 INFO Connecting to TGC socket...
2019-10-08 22:07:24,609 INFO Connected.
2019-10-08 22:07:24,609 INFO Recording brain data...
2019-10-08 22:08:04,351 INFO Connecting to TGC socket...
2019-10-08 22:08:05,363 INFO Connected.
2019-10-08 22:08:05,364 INFO Recording brain data...
2019-10-09 11:05:55,743 INFO Connecting to TGC socket...
2019-10-09 11:05:56,762 INFO Connected.
2019-10-09 11:05:56,763 INFO Recording brain data...
2019-10-09 11:05:58,922 ERROR Exception:
Traceback (most recent call last):
  File "recordEEGdata.py", line 116, in <module>
    conn.record_data()
  File "recordEEGdata.py", line 81, in record_data
    self.data = self.data.decode('utf-8')
UnicodeDecodeError: 'utf-8' codec can't decode byte 0xaa in position 0: invalid start byte
2019-10-09 11:05:58,923 ERROR No connection with TGC socket
2019-10-09 11:06:24,237 INFO Connecting to TGC socket...
2019-10-09 11:06:25,249 INFO Connected.
2019-10-09 11:06:25,250 INFO Recording brain data...
2019-10-09 11:07:29,017 INFO Connecting to TGC socket...
2019-10-09 11:07:30,027 INFO Connected.
2019-10-09 11:07:30,028 INFO Recording brain data...
2019-10-09 11:08:43,401 INFO Connecting to TGC socket...
2019-10-09 11:08:44,412 INFO Connected.
2019-10-09 11:08:44,413 INFO Recording brain data...
2019-10-09 11:08:45,189 ERROR Exception:
Traceback (most recent call last):
  File "recordEEGdata.py", line 116, in <module>
    conn.record_data()
  File "recordEEGdata.py", line 81, in record_data
    self.data = self.data.decode('utf-8')
UnicodeDecodeError: 'utf-8' codec can't decode byte 0xaa in position 0: invalid start byte
2019-10-09 11:08:45,190 ERROR No connection with TGC socket
2019-10-09 11:09:23,939 INFO Connecting to TGC socket...
2019-10-09 11:09:24,953 INFO Connected.
2019-10-09 11:09:24,954 INFO Recording brain data...
2019-10-09 11:11:25,503 INFO Connecting to TGC socket...
2019-10-09 11:11:26,509 INFO Connected.
2019-10-09 11:11:26,510 INFO Recording brain data...
2019-10-09 11:12:24,165 INFO Connecting to TGC socket...
2019-10-09 11:12:25,173 INFO Connected.
2019-10-09 11:12:25,173 INFO Recording brain data...
2019-10-09 11:14:32,037 INFO Connecting to TGC socket...
2019-10-09 11:14:33,044 INFO Connected.
2019-10-09 11:14:33,045 INFO Recording brain data...
2019-10-09 11:17:06,789 INFO Connecting to TGC socket...
2019-10-09 11:17:07,796 INFO Connected.
2019-10-09 11:17:07,796 INFO Recording brain data...
2019-10-09 13:41:47,691 INFO Connecting to TGC socket...
2019-10-09 13:41:48,700 INFO Connected.
2019-10-09 13:41:48,700 INFO Recording brain data...
2019-10-09 15:41:46,440 INFO Connecting to TGC socket...
2019-10-09 15:41:47,447 INFO Connected.
2019-10-09 15:41:47,447 INFO Recording brain data...
2019-10-09 16:17:14,973 INFO Connecting to TGC socket...
2019-10-09 16:17:15,981 INFO Connected.
2019-10-09 16:17:15,982 INFO Recording brain data...
2019-10-09 16:18:11,024 INFO Connecting to TGC socket...
2019-10-09 16:18:12,036 INFO Connected.
2019-10-09 16:18:12,037 INFO Recording brain data...
2019-10-09 16:57:25,799 INFO Connecting to TGC socket...
2019-10-09 16:57:26,806 INFO Connected.
2019-10-09 16:57:26,806 INFO Recording brain data...
2019-10-09 21:11:32,814 INFO Connecting to TGC socket...
2019-10-09 21:11:34,972 ERROR Exception:
Traceback (most recent call last):
  File "recordEEGdata.py", line 121, in <module>
    conn.connect(TGHOST, TGPORT)
  File "recordEEGdata.py", line 49, in connect
    self.sock = Telnet('localhost',13854)
  File "C:\Users\Raj Madheshia\AppData\Local\Programs\Python\Python37\lib\telnetlib.py", line 218, in __init__
    self.open(host, port, timeout)
  File "C:\Users\Raj Madheshia\AppData\Local\Programs\Python\Python37\lib\telnetlib.py", line 234, in open
    self.sock = socket.create_connection((host, port), timeout)
  File "C:\Users\Raj Madheshia\AppData\Local\Programs\Python\Python37\lib\socket.py", line 727, in create_connection
    raise err
  File "C:\Users\Raj Madheshia\AppData\Local\Programs\Python\Python37\lib\socket.py", line 716, in create_connection
    sock.connect(sa)
ConnectionRefusedError: [WinError 10061] No connection could be made because the target machine actively refused it
2019-10-09 21:11:34,975 ERROR No connection with TGC socket
2019-10-09 21:12:08,855 INFO Connecting to TGC socket...
2019-10-09 21:12:10,865 ERROR Exception:
Traceback (most recent call last):
  File "recordEEGdata.py", line 121, in <module>
    conn.connect(TGHOST, TGPORT)
  File "recordEEGdata.py", line 49, in connect
    self.sock = Telnet('localhost',13854)
  File "C:\Users\Raj Madheshia\AppData\Local\Programs\Python\Python37\lib\telnetlib.py", line 218, in __init__
    self.open(host, port, timeout)
  File "C:\Users\Raj Madheshia\AppData\Local\Programs\Python\Python37\lib\telnetlib.py", line 234, in open
    self.sock = socket.create_connection((host, port), timeout)
  File "C:\Users\Raj Madheshia\AppData\Local\Programs\Python\Python37\lib\socket.py", line 727, in create_connection
    raise err
  File "C:\Users\Raj Madheshia\AppData\Local\Programs\Python\Python37\lib\socket.py", line 716, in create_connection
    sock.connect(sa)
ConnectionRefusedError: [WinError 10061] No connection could be made because the target machine actively refused it
2019-10-09 21:12:10,867 ERROR No connection with TGC socket
2019-10-09 21:16:01,462 INFO Connecting to TGC socket...
2019-10-09 21:16:02,470 INFO Connected.
2019-10-09 21:16:02,571 INFO Recording brain data...
